Workbook
Name ListaFiltrada: OFFSET(Lista!$D$2,0,0,MAX(1,MAX(Lista!$B$2:$B$647)),1)

Sheet Calculadora
B2: Calculadora nutricional (Tabla INTA 2018)
B4: Producto (escribe parte del nombre): | C4: Leche en polvo 26% MG con Vit. D | G4: Cómo usarla: | H4: =IFERROR(MATCH(C4,Datos!$C$2:$C$648,0),0) -> 15
B5: Gramos que necesitas: | C5: 100 | D5: g | G5: 1. Haz clic en la celda amarilla C4, escribe parte del nombre (ej.: olvo) y presiona Enter.
B6: Grupo / Fuente: | C6: =IF($H$4=0,"⚠ Abre la lista de C4 y elige un producto",INDEX(Datos!$B$2:$B$648,$H$4)&" · Fuente "&INDEX(Datos!$D$2:$D$648,$H$4)) -> Leche y Derivados · Fuente 1 | G6: 2. Vuelve a seleccionar C4 y abre la flecha ▼: solo aparecen los productos que contienen ese texto.
G7: 3. Elige el producto. La columna 'Por 100 g' muestra los valores de la tabla.
B8: Componente | C8: Unidad | D8: Por 100 g | E8: ="Por "&$C$5&" g" -> Por 100 g | F8: Origen | G8: 4. Escribe los gramos en C5 (por defecto 100): la última columna se ajusta proporcionalmente.
B9: Energía | C9: kcal | D9: =IF($H$4=0,"",INDEX(Datos!$E$2:$E$648,$H$4)) -> 496 | E9: =IF(ISNUMBER(D9),D9*$C$5/100,D9) -> 496 | F9: =IF($H$4=0,"",IF(COUNTIFS('Valores completados'!$A$2:$A$6021,$C$4,'Valores completados'!$B$2:$B$6021,B9)>0,"≈ estimado (USDA)",IF(ISNUMBER(D9),"Tabla INTA",""))) -> Tabla INTA | G9: Para buscar otro producto, vuelve a escribir en C4 sobre el nombre actual.
B10: Humedad | C10: g | D10: =IF($H$4=0,"",INDEX(Datos!$F$2:$F$648,$H$4)) -> 2.5 | E10: =IF(ISNUMBER(D10),D10*$C$5/100,D10) -> 2.5 | F10: =IF($H$4=0,"",IF(COUNTIFS('Valores completados'!$A$2:$A$6021,$C$4,'Valores completados'!$B$2:$B$6021,B10)>0,"≈ estimado (USDA)",IF(ISNUMBER(D10),"Tabla INTA",""))) -> Tabla INTA | G10: S/I = sin información (no se puede calcular). Valores de bebidas/líquidos son por 100 ml.
B11: Cenizas | C11: g | D11: =IF($H$4=0,"",INDEX(Datos!$G$2:$G$648,$H$4)) -> 6.1 | E11: =IF(ISNUMBER(D11),D11*$C$5/100,D11) -> 6.1 | F11: =IF($H$4=0,"",IF(COUNTIFS('Valores completados'!$A$2:$A$6021,$C$4,'Valores completados'!$B$2:$B$6021,B11)>0,"≈ estimado (USDA)",IF(ISNUMBER(D11),"Tabla INTA",""))) -> Tabla INTA
B12: Proteínas | C12: g | D12: =IF($H$4=0,"",INDEX(Datos!$H$2:$H$648,$H$4)) -> 26.3 | E12: =IF(ISNUMBER(D12),D12*$C$5/100,D12) -> 26.3 | F12: =IF($H$4=0,"",IF(COUNTIFS('Valores completados'!$A$2:$A$6021,$C$4,'Valores completados'!$B$2:$B$6021,B12)>0,"≈ estimado (USDA)",IF(ISNUMBER(D12),"Tabla INTA",""))) -> Tabla INTA
B13: H de C disponibles | C13: g | D13: =IF($H$4=0,"",INDEX(Datos!$I$2:$I$648,$H$4)) -> 38.4 | E13: =IF(ISNUMBER(D13),D13*$C$5/100,D13) -> 38.4 | F13: =IF($H$4=0,"",IF(COUNTIFS('Valores completados'!$A$2:$A$6021,$C$4,'Valores completados'!$B$2:$B$6021,B13)>0,"≈ estimado (USDA)",IF(ISNUMBER(D13),"Tabla INTA",""))) -> Tabla INTA
B14: Azúcares totales | C14: g | D14: =IF($H$4=0,"",INDEX(Datos!$J$2:$J$648,$H$4)) -> 38.4 | E14: =IF(ISNUMBER(D14),D14*$C$5/100,D14) -> 38.4 | F14: =IF($H$4=0,"",IF(COUNTIFS('Valores completados'!$A$2:$A$6021,$C$4,'Valores completados'!$B$2:$B$6021,B14)>0,"≈ estimado (USDA)",IF(ISNUMBER(D14),"Tabla INTA",""))) -> Tabla INTA
B15: Fibra dietética total | C15: g | D15: =IF($H$4=0,"",INDEX(Datos!$K$2:$K$648,$H$4)) -> 0 | E15: =IF(ISNUMBER(D15),D15*$C$5/100,D15) -> 0 | F15: =IF($H$4=0,"",IF(COUNTIFS('Valores completados'!$A$2:$A$6021,$C$4,'Valores completados'!$B$2:$B$6021,B15)>0,"≈ estimado (USDA)",IF(ISNUMBER(D15),"Tabla INTA",""))) -> Tabla INTA
B16: Lípidos totales | C16: g | D16: =IF($H$4=0,"",INDEX(Datos!$L$2:$L$648,$H$4)) -> 26.7 | E16: =IF(ISNUMBER(D16),D16*$C$5/100,D16) -> 26.7 | F16: =IF($H$4=0,"",IF(COUNTIFS('Valores completados'!$A$2:$A$6021,$C$4,'Valores completados'!$B$2:$B$6021,B16)>0,"≈ estimado (USDA)",IF(ISNUMBER(D16),"Tabla INTA",""))) -> Tabla INTA
B17: Ác. grasos saturados | C17: g | D17: =IF($H$4=0,"",INDEX(Datos!$M$2:$M$648,$H$4)) -> 16.74 | E17: =IF(ISNUMBER(D17),D17*$C$5/100,D17) -> 16.74 | F17: =IF($H$4=0,"",IF(COUNTIFS('Valores completados'!$A$2:$A$6021,$C$4,'Valores completados'!$B$2:$B$6021,B17)>0,"≈ estimado (USDA)",IF(ISNUMBER(D17),"Tabla INTA",""))) -> Tabla INTA
B18: Ác. grasos monoinsaturados | C18: g | D18: =IF($H$4=0,"",INDEX(Datos!$N$2:$N$648,$H$4)) -> 7.92 | E18: =IF(ISNUMBER(D18),D18*$C$5/100,D18) -> 7.92 | F18: =IF($H$4=0,"",IF(COUNTIFS('Valores completados'!$A$2:$A$6021,$C$4,'Valores completados'!$B$2:$B$6021,B18)>0,"≈ estimado (USDA)",IF(ISNUMBER(D18),"Tabla INTA",""))) -> Tabla INTA
B19: Ác. grasos poliinsaturados | C19: g | D19: =IF($H$4=0,"",INDEX(Datos!$O$2:$O$648,$H$4)) -> 0.67 | E19: =IF(ISNUMBER(D19),D19*$C$5/100,D19) -> 0.67 | F19: =IF($H$4=0,"",IF(COUNTIFS('Valores completados'!$A$2:$A$6021,$C$4,'Valores completados'!$B$2:$B$6021,B19)>0,"≈ estimado (USDA)",IF(ISNUMBER(D19),"Tabla INTA",""))) -> Tabla INTA
B20: Ác. grasos trans | C20: g | D20: =IF($H$4=0,"",INDEX(Datos!$P$2:$P$648,$H$4)) -> S/I | E20: =IF(ISNUMBER(D20),D20*$C$5/100,D20) -> S/I | F20: =IF($H$4=0,"",IF(COUNTIFS('Valores completados'!$A$2:$A$6021,$C$4,'Valores completados'!$B$2:$B$6021,B20)>0,"≈ estimado (USDA)",IF(ISNUMBER(D20),"Tabla INTA","")))
B21: Colesterol | C21: mg | D21: =IF($H$4=0,"",INDEX(Datos!$Q$2:$Q$648,$H$4)) -> 97 | E21: =IF(ISNUMBER(D21),D21*$C$5/100,D21) -> 97 | F21: =IF($H$4=0,"",IF(COUNTIFS('Valores completados'!$A$2:$A$6021,$C$4,'Valores completados'!$B$2:$B$6021,B21)>0,"≈ estimado (USDA)",IF(ISNUMBER(D21),"Tabla INTA",""))) -> Tabla INTA
B22: Vitamina A | C22: ug EAR | D22: =IF($H$4=0,"",INDEX(Datos!$R$2:$R$648,$H$4)) -> 258 | E22: =IF(ISNUMBER(D22),D22*$C$5/100,D22) -> 258 | F22: =IF($H$4=0,"",IF(COUNTIFS('Valores completados'!$A$2:$A$6021,$C$4,'Valores completados'!$B$2:$B$6021,B22)>0,"≈ estimado (USDA)",IF(ISNUMBER(D22),"Tabla INTA",""))) -> Tabla INTA
B23: Vitamina C | C23: mg | D23: =IF($H$4=0,"",INDEX(Datos!$S$2:$S$648,$H$4)) -> 8.6 | E23: =IF(ISNUMBER(D23),D23*$C$5/100,D23) -> 8.6 | F23: =IF($H$4=0,"",IF(COUNTIFS('Valores completados'!$A$2:$A$6021,$C$4,'Valores completados'!$B$2:$B$6021,B23)>0,"≈ estimado (USDA)",IF(ISNUMBER(D23),"Tabla INTA",""))) -> Tabla INTA
B24: Vitamina D | C24: ug | D24: =IF($H$4=0,"",INDEX(Datos!$T$2:$T$648,$H$4)) -> 10.5 | E24: =IF(ISNUMBER(D24),D24*$C$5/100,D24) -> 10.5 | F24: =IF($H$4=0,"",IF(COUNTIFS('Valores completados'!$A$2:$A$6021,$C$4,'Valores completados'!$B$2:$B$6021,B24)>0,"≈ estimado (USDA)",IF(ISNUMBER(D24),"Tabla INTA",""))) -> Tabla INTA
B25: Vitamina E | C25: mg ET | D25: =IF($H$4=0,"",INDEX(Datos!$U$2:$U$648,$H$4)) -> 0.6 | E25: =IF(ISNUMBER(D25),D25*$C$5/100,D25) -> 0.6 | F25: =IF($H$4=0,"",IF(COUNTIFS('Valores completados'!$A$2:$A$6021,$C$4,'Valores completados'!$B$2:$B$6021,B25)>0,"≈ estimado (USDA)",IF(ISNUMBER(D25),"Tabla INTA",""))) -> Tabla INTA
B26: Vitamina K | C26: ug | D26: =IF($H$4=0,"",INDEX(Datos!$V$2:$V$648,$H$4)) -> 2.2 | E26: =IF(ISNUMBER(D26),D26*$C$5/100,D26) -> 2.2 | F26: =IF($H$4=0,"",IF(COUNTIFS('Valores completados'!$A$2:$A$6021,$C$4,'Valores completados'!$B$2:$B$6021,B26)>0,"≈ estimado (USDA)",IF(ISNUMBER(D26),"Tabla INTA",""))) -> Tabla INTA
B27: Vitamina B1 | C27: mg | D27: =IF($H$4=0,"",INDEX(Datos!$W$2:$W$648,$H$4)) -> 0.3 | E27: =IF(ISNUMBER(D27),D27*$C$5/100,D27) -> 0.3 | F27: =IF($H$4=0,"",IF(COUNTIFS('Valores completados'!$A$2:$A$6021,$C$4,'Valores completados'!$B$2:$B$6021,B27)>0,"≈ estimado (USDA)",IF(ISNUMBER(D27),"Tabla INTA",""))) -> Tabla INTA
B28: Vitamina B2 | C28: mg | D28: =IF($H$4=0,"",INDEX(Datos!$X$2:$X$648,$H$4)) -> 1.2 | E28: =IF(ISNUMBER(D28),D28*$C$5/100,D28) -> 1.2 | F28: =IF($H$4=0,"",IF(COUNTIFS('Valores completados'!$A$2:$A$6021,$C$4,'Valores completados'!$B$2:$B$6021,B28)>0,"≈ estimado (USDA)",IF(ISNUMBER(D28),"Tabla INTA",""))) -> Tabla INTA
B29: Niacina | C29: mg EN | D29: =IF($H$4=0,"",INDEX(Datos!$Y$2:$Y$648,$H$4)) -> 0.7 | E29: =IF(ISNUMBER(D29),D29*$C$5/100,D29) -> 0.7 | F29: =IF($H$4=0,"",IF(COUNTIFS('Valores completados'!$A$2:$A$6021,$C$4,'Valores completados'!$B$2:$B$6021,B29)>0,"≈ estimado (USDA)",IF(ISNUMBER(D29),"Tabla INTA",""))) -> Tabla INTA
B30: Vitamina B6 | C30: mg | D30: =IF($H$4=0,"",INDEX(Datos!$Z$2:$Z$648,$H$4)) -> 0.3 | E30: =IF(ISNUMBER(D30),D30*$C$5/100,D30) -> 0.3 | F30: =IF($H$4=0,"",IF(COUNTIFS('Valores completados'!$A$2:$A$6021,$C$4,'Valores completados'!$B$2:$B$6021,B30)>0,"≈ estimado (USDA)",IF(ISNUMBER(D30),"Tabla INTA",""))) -> Tabla INTA
B31: Ác. pantoténico | C31: mg | D31: =IF($H$4=0,"",INDEX(Datos!$AA$2:$AA$648,$H$4)) -> 2.3 | E31: =IF(ISNUMBER(D31),D31*$C$5/100,D31) -> 2.3 | F31: =IF($H$4=0,"",IF(COUNTIFS('Valores completados'!$A$2:$A$6021,$C$4,'Valores completados'!$B$2:$B$6021,B31)>0,"≈ estimado (USDA)",IF(ISNUMBER(D31),"Tabla INTA",""))) -> Tabla INTA
B32: Vitamina B12 | C32: ug | D32: =IF($H$4=0,"",INDEX(Datos!$AB$2:$AB$648,$H$4)) -> 3.3 | E32: =IF(ISNUMBER(D32),D32*$C$5/100,D32) -> 3.3 | F32: =IF($H$4=0,"",IF(COUNTIFS('Valores completados'!$A$2:$A$6021,$C$4,'Valores completados'!$B$2:$B$6021,B32)>0,"≈ estimado (USDA)",IF(ISNUMBER(D32),"Tabla INTA",""))) -> Tabla INTA
B33: Folatos | C33: ug EFA | D33: =IF($H$4=0,"",INDEX(Datos!$AC$2:$AC$648,$H$4)) -> 37 | E33: =IF(ISNUMBER(D33),D33*$C$5/100,D33) -> 37 | F33: =IF($H$4=0,"",IF(COUNTIFS('Valores completados'!$A$2:$A$6021,$C$4,'Valores completados'!$B$2:$B$6021,B33)>0,"≈ estimado (USDA)",IF(ISNUMBER(D33),"Tabla INTA",""))) -> Tabla INTA
B34: Sodio | C34: mg | D34: =IF($H$4=0,"",INDEX(Datos!$AD$2:$AD$648,$H$4)) -> 371 | E34: =IF(ISNUMBER(D34),D34*$C$5/100,D34) -> 371 | F34: =IF($H$4=0,"",IF(COUNTIFS('Valores completados'!$A$2:$A$6021,$C$4,'Valores completados'!$B$2:$B$6021,B34)>0,"≈ estimado (USDA)",IF(ISNUMBER(D34),"Tabla INTA",""))) -> Tabla INTA
B35: Potasio | C35: mg | D35: =IF($H$4=0,"",INDEX(Datos!$AE$2:$AE$648,$H$4)) -> 1330 | E35: =IF(ISNUMBER(D35),D35*$C$5/100,D35) -> 1330 | F35: =IF($H$4=0,"",IF(COUNTIFS('Valores completados'!$A$2:$A$6021,$C$4,'Valores completados'!$B$2:$B$6021,B35)>0,"≈ estimado (USDA)",IF(ISNUMBER(D35),"Tabla INTA",""))) -> Tabla INTA
B36: Calcio | C36: mg | D36: =IF($H$4=0,"",INDEX(Datos!$AF$2:$AF$648,$H$4)) -> 912 | E36: =IF(ISNUMBER(D36),D36*$C$5/100,D36) -> 912 | F36: =IF($H$4=0,"",IF(COUNTIFS('Valores completados'!$A$2:$A$6021,$C$4,'Valores completados'!$B$2:$B$6021,B36)>0,"≈ estimado (USDA)",IF(ISNUMBER(D36),"Tabla INTA",""))) -> Tabla INTA
B37: Fósforo | C37: mg | D37: =IF($H$4=0,"",INDEX(Datos!$AG$2:$AG$648,$H$4)) -> 776 | E37: =IF(ISNUMBER(D37),D37*$C$5/100,D37) -> 776 | F37: =IF($H$4=0,"",IF(COUNTIFS('Valores completados'!$A$2:$A$6021,$C$4,'Valores completados'!$B$2:$B$6021,B37)>0,"≈ estimado (USDA)",IF(ISNUMBER(D37),"Tabla INTA",""))) -> Tabla INTA
B38: Magnesio | C38: mg | D38: =IF($H$4=0,"",INDEX(Datos!$AH$2:$AH$648,$H$4)) -> 85 | E38: =IF(ISNUMBER(D38),D38*$C$5/100,D38) -> 85 | F38: =IF($H$4=0,"",IF(COUNTIFS('Valores completados'!$A$2:$A$6021,$C$4,'Valores completados'!$B$2:$B$6021,B38)>0,"≈ estimado (USDA)",IF(ISNUMBER(D38),"Tabla INTA",""))) -> Tabla INTA
B39: Hierro | C39: mg | D39: =IF($H$4=0,"",INDEX(Datos!$AI$2:$AI$648,$H$4)) -> 0.5 | E39: =IF(ISNUMBER(D39),D39*$C$5/100,D39) -> 0.5 | F39: =IF($H$4=0,"",IF(COUNTIFS('Valores completados'!$A$2:$A$6021,$C$4,'Valores completados'!$B$2:$B$6021,B39)>0,"≈ estimado (USDA)",IF(ISNUMBER(D39),"Tabla INTA",""))) -> Tabla INTA
B40: Zinc | C40: mg | D40: =IF($H$4=0,"",INDEX(Datos!$AJ$2:$AJ$648,$H$4)) -> 3.3 | E40: =IF(ISNUMBER(D40),D40*$C$5/100,D40) -> 3.3 | F40: =IF($H$4=0,"",IF(COUNTIFS('Valores completados'!$A$2:$A$6021,$C$4,'Valores completados'!$B$2:$B$6021,B40)>0,"≈ estimado (USDA)",IF(ISNUMBER(D40),"Tabla INTA",""))) -> Tabla INTA
B41: Cobre | C41: mg | D41: =IF($H$4=0,"",INDEX(Datos!$AK$2:$AK$648,$H$4)) -> 0.1 | E41: =IF(ISNUMBER(D41),D41*$C$5/100,D41) -> 0.1 | F41: =IF($H$4=0,"",IF(COUNTIFS('Valores completados'!$A$2:$A$6021,$C$4,'Valores completados'!$B$2:$B$6021,B41)>0,"≈ estimado (USDA)",IF(ISNUMBER(D41),"Tabla INTA",""))) -> Tabla INTA
B42: Selenio | C42: ug | D42: =IF($H$4=0,"",INDEX(Datos!$AL$2:$AL$648,$H$4)) -> 16.3 | E42: =IF(ISNUMBER(D42),D42*$C$5/100,D42) -> 16.3 | F42: =IF($H$4=0,"",IF(COUNTIFS('Valores completados'!$A$2:$A$6021,$C$4,'Valores completados'!$B$2:$B$6021,B42)>0,"≈ estimado (USDA)",IF(ISNUMBER(D42),"Tabla INTA",""))) -> Tabla INTA
...

Sheet Datos
A1: N° | B1: Grupo | C1: Producto | D1: Fuente | E1: Energía (kcal) | F1: Humedad (g) | G1: Cenizas (g) | H1: Proteínas (g) | I1: H de C disponibles (g) | J1: Azúcares totales (g) | K1: Fibra dietética total (g) | L1: Lípidos totales (g) | M1: Ác. grasos saturados (g) | N1: Ác. grasos monoinsaturados (g) | O1: Ác. grasos poliinsaturados (g) | P1: Ác. grasos trans (g) | Q1: Colesterol (mg) | R1: Vitamina A (ug EAR) | S1: Vitamina C (mg) | T1: Vitamina D (ug) | U1: Vitamina E (mg ET) | V1: Vitamina K (ug) | W1: Vitamina B1 (mg) | X1: Vitamina B2 (mg) | Y1: Niacina (mg EN) | Z1: Vitamina B6 (mg) | AA1: Ác. pantoténico (mg) | AB1: Vitamina B12 (ug) | AC1: Folatos (ug EFA) | AD1: Sodio (mg) | AE1: Potasio (mg) | AF1: Calcio (mg) | AG1: Fósforo (mg) | AH1: Magnesio (mg) | AI1: Hierro (mg) | AJ1: Zinc (mg) | AK1: Cobre (mg) | AL1: Selenio (ug) | AM1: Alcohol (g)
A2: 1 | B2: Leche y Derivados | C2: Leche materna | D2: 1 | E2: 70 | F2: 87.5 | G2: 0.2 | H2: 1 | I2: 6.9 | J2: 6.9 | K2: 0 | L2: 4.4 | M2: 2.01 | N2: 1.66 | O2: 0.5 | P2: S/I | Q2: 14 | R2: 61 | S2: 5 | T2: 0.1 | U2: 0.1 | V2: 0.3 | W2: 0 | X2: 0 | Y2: 0.2 | Z2: 0 | AA2: 0.2 | AB2: 0.1 | AC2: 5 | AD2: 17 | AE2: 51 | AF2: 32 | AG2: 14 | AH2: 3 | AI2: 0 | AJ2: 0.2 | AK2: 0.1 | AL2: 1.8 | AM2: 0
A3: 2 | B3: Leche y Derivados | C3: Leche de burra | D3: 2 | E3: 41 | F3: 90.4 | G3: 0.4 | H3: 1.6 | I3: 6.7 | J3: S/I | K3: 0 | L3: 0.9 | M3: S/I | N3: S/I | O3: S/I | P3: S/I | Q3: S/I | R3: S/I | S3: 1.7 | T3: S/I | U3: S/I | V3: S/I | W3: 0 | X3: 0.1 | Y3: 0.1 | Z3: S/I | AA3: S/I | AB3: S/I | AC3: S/I | AD3: S/I | AE3: S/I | AF3: 138 | AG3: 60 | AH3: S/I | AI3: S/I | AJ3: S/I | AK3: S/I | AL3: S/I | AM3: 0
A4: 3 | B4: Leche y Derivados | C4: Leche de cabra con Vit. D | D4: 1 | E4: 69 | F4: 87 | G4: 0.8 | H4: 3.6 | I4: 4.5 | J4: 4.5 | K4: 0 | L4: 4.1 | M4: 2.67 | N4: 1.11 | O4: 0.15 | P4: S/I | Q4: 11 | R4: 57 | S4: 1.3 | T4: 1.3 | U4: 0.1 | V4: 0.3 | W4: 0.1 | X4: 0.1 | Y4: 0.3 | Z4: 0.1 | AA4: 0.3 | AB4: 0.1 | AC4: 1 | AD4: 50 | AE4: 204 | AF4: 134 | AG4: 111 | AH4: 14 | AI4: 0.1 | AJ4: 0.3 | AK4: 0.1 | AL4: 1.4 | AM4: 0
A5: 4 | B5: Leche y Derivados | C5: Leche fluida entera (fuente 1) | D5: 1 | E5: 64 | F5: 87.7 | G5: 0.7 | H5: 3.3 | I5: 4.7 | J5: 4.7 | K5: 0 | L5: 3.7 | M5: 2.28 | N5: 1.06 | O5: 0.14 | P5: S/I | Q5: 14 | R5: 33 | S5: 1.5 | T5: 0.1 | U5: 0.1 | V5: 0.3 | W5: 0 | X5: 0.2 | Y5: 0.1 | Z5: 0 | AA5: 0.3 | AB5: 0.4 | AC5: 5 | AD5: 49 | AE5: 151 | AF5: 119 | AG5: 93 | AH5: 13 | AI5: 0.1 | AJ5: 0.4 | AK5: 0 | AL5: 2 | AM5: 0
A6: 5 | B6: Leche y Derivados | C6: Leche fluida entera (fuente 2) | D6: 2 | E6: 58 | F6: 88.1 | G6: 0.6 | H6: 3.2 | I6: 5.6 | J6: 5.1 | K6: 0 | L6: 2.5 | M6: 2.09 | N6: 0.96 | O6: 0.12 | P6: S/I | Q6: 13.5 | R6: 31.1 | S6: 1 | T6: 0.1 | U6: 0.1 | V6: 0.3 | W6: 0.1 | X6: 0.1 | Y6: 0.1 | Z6: 0 | AA6: 0.3 | AB6: 0.4 | AC6: 4.9 | AD6: 59.7 | AE6: 141.8 | AF6: 123 | AG6: 95 | AH6: 13.5 | AI6: 0.1 | AJ6: 0.4 | AK6: 0 | AL6: 3.7 | AM6: 0
A7: 6 | B7: Leche y Derivados | C7: Leche entera con sabor | D7: 3 | E7: 80 | F7: 82.9 | G7: 0.8 | H7: 2.4 | I7: 10.5 | J7: 9.2 | K7: 0.5 | L7: 2.9 | M7: 1.84 | N7: 0.87 | O7: 0.15 | P7: S/I | Q7: 6.4 | R7: 29 | S7: 0.9 | T7: 1.3 | U7: 0.1 | V7: 0.3 | W7: 0 | X7: 0.2 | Y7: 0.1 | Z7: 0 | AA7: 0.3 | AB7: 0.3 | AC7: 4.7 | AD7: 59.6 | AE7: 167 | AF7: 112 | AG7: 100 | AH7: 13 | AI7: 0.2 | AJ7: 0.4 | AK7: 0.1 | AL7: 1.2 | AM7: 0
A8: 7 | B8: Leche y Derivados | C8: Leche semidescremada | D8: 3 | E8: 42 | F8: 90.2 | G8: 0.8 | H8: 2.6 | I8: 5.1 | J8: 3.2 | K8: 0 | L8: 1.3 | M8: 0.83 | N8: 0.37 | O8: 0.05 | P8: 0.06 | Q8: 8 | R8: 50 | S8: 0.2 | T8: 1.1 | U8: 0 | V8: 0.2 | W8: 0 | X8: 0.2 | Y8: 0.1 | Z8: 0 | AA8: 0.3 | AB8: 0.5 | AC8: 4.5 | AD8: 42.7 | AE8: 127.2 | AF8: 109 | AG8: 83.6 | AH8: 10 | AI8: 0 | AJ8: 0.4 | AK8: 0 | AL8: 2.3 | AM8: 0
A9: 8 | B9: Leche y Derivados | C9: Leche semidescremada con sabor | D9: 1 | E9: 76 | F9: 82.2 | G9: 0.8 | H9: 3 | I9: 11.4 | J9: 9.6 | K9: 0.7 | L9: 1.9 | M9: 1.18 | N9: 0.46 | O9: 0.09 | P9: S/I | Q9: 8 | R9: 64 | S9: 0 | T9: 1.2 | U9: 0 | V9: 0.2 | W9: 0.1 | X9: 0.2 | Y9: 0.2 | Z9: 0 | AA9: 0.5 | AB9: 0.3 | AC9: 2 | AD9: 66 | AE9: 169 | AF9: 109 | AG9: 102 | AH9: 14 | AI9: 0.2 | AJ9: 0.4 | AK9: 0.1 | AL9: 3.4 | AM9: 0
A10: 9 | B10: Leche y Derivados | C10: Leche semidescremada con sabor chocolate | D10: 4 | E10: 52 | F10: 88.6 | G10: 0.8 | H10: 3.2 | I10: 5.6 | J10: 5 | K10: 0 | L10: 1.8 | M10: 1.15 | N10: 0.52 | O10: 0.05 | P10: 0.1 | Q10: 6 | R10: 40 | S10: 0 | T10: 0.3 | U10: 1 | V10: 0.1 | W10: 0 | X10: 0.2 | Y10: 0.1 | Z10: 0.1 | AA10: 0.5 | AB10: 0.2 | AC10: 5 | AD10: 70 | AE10: 168 | AF10: 93 | AG10: 84 | AH10: 13 | AI10: 0.2 | AJ10: 0.5 | AK10: 0 | AL10: 1.9 | AM10: 0
A11: 10 | B11: Leche y Derivados | C11: Leche semidescremada con sabor frutilla | D11: 4 | E11: 54 | F11: 88.2 | G11: 0.8 | H11: 3.1 | I11: 6 | J11: 5.5 | K11: 0 | L11: 1.9 | M11: 1.22 | N11: 0.55 | O11: 0.05 | P11: 0.1 | Q11: 6 | R11: 40 | S11: 0 | T11: 0.3 | U11: 1 | V11: 0.1 | W11: 0 | X11: 0.2 | Y11: 0.1 | Z11: 0 | AA11: 0.4 | AB11: 0.5 | AC11: 5 | AD11: 60 | AE11: 150 | AF11: 104 | AG11: 84 | AH11: 11 | AI11: 0 | AJ11: 0.4 | AK11: 0 | AL11: 3.3 | AM11: 0
A12: 11 | B12: Leche y Derivados | C12: Leche semidescremada sin lactosa | D12: 4 | E12: 44 | F12: 90.2 | G12: 0.8 | H12: 3.1 | I12: 4.6 | J12: 4.6 | K12: 0 | L12: 1.3 | M12: 1 | N12: 0.35 | O12: 0.05 | P12: 0.1 | Q12: 6 | R12: 50 | S12: 0 | T12: 0.4 | U12: 0 | V12: 0.1 | W12: 0 | X12: 0.2 | Y12: 0.1 | Z12: 0 | AA12: 0.4 | AB12: 0.5 | AC12: 5 | AD12: 60 | AE12: 150 | AF12: 101 | AG12: 95 | AH12: 11 | AI12: 0 | AJ12: 0.4 | AK12: 0 | AL12: 3.3 | AM12: 0
A13: 12 | B13: Leche y Derivados | C13: Leche descremada (fuente 4) | D13: 4 | E13: 32 | F13: 91.1 | G13: 0.8 | H13: 3.3 | I13: 4.7 | J13: 4.7 | K13: 0 | L13: 0.1 | M13: 0.03 | N13: 0.01 | O13: 0 | P13: 0 | Q13: 0.2 | R13: 61 | S13: 0 | T13: 1.2 | U13: 0 | V13: 0 | W13: 0 | X13: 0.2 | Y13: 0.1 | Z13: 0 | AA13: 0.4 | AB13: 0.5 | AC13: 5 | AD13: 32 | AE13: 156 | AF13: 115 | AG13: 90 | AH13: 11 | AI13: 0 | AJ13: 0.4 | AK13: 0 | AL13: 3.1 | AM13: 0
A14: 13 | B14: Leche y Derivados | C14: Leche descremada (fuente 1) | D14: 1 | E14: 42 | F14: 89.9 | G14: 0.8 | H14: 3.4 | I14: 5 | J14: 5.2 | K14: 0 | L14: 1 | M14: 0.63 | N14: 0.28 | O14: 0.04 | P14: S/I | Q14: 5 | R14: 14 | S14: 0 | T14: 0 | U14: 0 | V14: 0.1 | W14: 0 | X14: 0.2 | Y14: 0.1 | Z14: 0 | AA14: 0.4 | AB14: 0.5 | AC14: 5 | AD14: 44 | AE14: 150 | AF14: 125 | AG14: 95 | AH14: 11 | AI14: 0 | AJ14: 0.4 | AK14: 0 | AL14: 3.3 | AM14: 0
A15: 14 | B15: Leche y Derivados | C15: Leche en polvo 26% MG | D15: 2 | E15: 489 | F15: 3.2 | G15: 6.2 | H15: 28.6 | I15: 36.7 | J15: 36.7 | K15: 0 | L15: 25.3 | M15: 16.19 | N15: 7.62 | O15: 1.44 | P15: S/I | Q15: 80 | R15: 281.3 | S15: 9.4 | T15: 0.5 | U15: 0.6 | V15: 2.2 | W15: 0.3 | X15: 2.1 | Y15: 0.6 | Z15: 0.3 | AA15: 2.3 | AB15: 3.3 | AC15: 37.5 | AD15: 394.6 | AE15: 1307 | AF15: 912.5 | AG15: 775 | AH15: 84.4 | AI15: 0.5 | AJ15: 3.3 | AK15: 0.1 | AL15: 16.2 | AM15: 0
A16: 15 | B16: Leche y Derivados | C16: Leche en polvo 26% MG con Vit. D | D16: 1 | E16: 496 | F16: 2.5 | G16: 6.1 | H16: 26.3 | I16: 38.4 | J16: 38.4 | K16: 0 | L16: 26.7 | M16: 16.74 | N16: 7.92 | O16: 0.67 | P16: S/I | Q16: 97 | R16: 258 | S16: 8.6 | T16: 10.5 | U16: 0.6 | V16: 2.2 | W16: 0.3 | X16: 1.2 | Y16: 0.7 | Z16: 0.3 | AA16: 2.3 | AB16: 3.3 | AC16: 37 | AD16: 371 | AE16: 1330 | AF16: 912 | AG16: 776 | AH16: 85 | AI16: 0.5 | AJ16: 3.3 | AK16: 0.1 | AL16: 16.3 | AM16: 0
A17: 16 | B17: Leche y Derivados | C17: Leche en polvo 18% MG extra calcio | D17: 2 | E17: 454 | F17: 4.2 | G17: 6.1 | H17: 29.1 | I17: 42.7 | J17: 38.4 | K17: 0 | L17: 17.9 | M17: 11.46 | N17: 5.39 | O17: 1.02 | P17: S/I | Q17: 32 | R17: 258 | S17: 75 | T17: 10.5 | U17: 0.6 | V17: 2.2 | W17: 0.3 | X17: 1.2 | Y17: 0.6 | Z17: 0.3 | AA17: 2.3 | AB17: 3.2 | AC17: 37 | AD17: 371 | AE17: 1330 | AF17: 1610 | AG17: 865 | AH17: 85 | AI17: 15 | AJ17: 3.3 | AK17: 0.1 | AL17: 16.3 | AM17: 0
A18: 17 | B18: Leche y Derivados | C18: Leche en polvo 12% MG | D18: 2 | E18: 406 | F18: 5.4 | G18: 7.1 | H18: 34.6 | I18: 41.8 | J18: 37.3 | K18: 0 | L18: 11.1 | M18: 7.1 | N18: 3.34 | O18: 0.63 | P18: S/I | Q18: 19.8 | R18: 111 | S18: 8.3 | T18: 10.2 | U18: 0.6 | V18: 2.1 | W18: 0.2 | X18: 1.7 | Y18: 0.6 | Z18: 0.3 | AA18: 2.2 | AB18: 3.2 | AC18: 35.9 | AD18: 534.9 | AE18: 1521.6 | AF18: 884.6 | AG18: 946 | AH18: 82.4 | AI18: 0.5 | AJ18: 3.2 | AK18: 0.1 | AL18: 15.8 | AM18: 0
A19: 18 | B19: Leche y Derivados | C19: Leche en polvo descremada | D19: 1 | E19: 358 | F19: 4 | G19: 8 | H19: 35.1 | I19: 52.2 | J19: 52.2 | K19: 0 | L19: 0.7 | M19: 0.47 | N19: 0.19 | O19: 0.03 | P19: S/I | Q19: 18 | R19: 4 | S19: 5.6 | T19: 0 | U19: 0 | V19: 0 | W19: 0.4 | X19: 1.7 | Y19: 0.9 | Z19: 0.4 | AA19: 3.2 | AB19: 4 | AC19: 50 | AD19: 549 | AE19: 1705 | AF19: 1231 | AG19: 985 | AH19: 117 | AI19: 0.3 | AJ19: 4.4 | AK19: 0 | AL19: 27.3 | AM19: 0
A20: 19 | B20: Leche y Derivados | C20: Leche en polvo descremada extra calcio | D20: 4 | E20: 349 | F20: 6.8 | G20: 7.9 | H20: 31 | I20: 52.8 | J20: 52.5 | K20: 0 | L20: 1.5 | M20: 0.9 | N20: 0.2 | O20: 0.03 | P20: 0.1 | Q20: 20 | R20: 450 | S20: 85 | T20: 6 | U20: 18 | V20: 100 | W20: 0.4 | X20: 1.6 | Y20: 1 | Z20: 0.4 | AA20: 3.6 | AB20: 4 | AC20: 50 | AD20: 450 | AE20: 1794 | AF20: 2000 | AG20: 900 | AH20: 240 | AI20: 17 | AJ20: 10 | AK20: 0 | AL20: 27.3 | AM20: 0
A21: 20 | B21: Leche y Derivados | C21: Leche en polvo Purita Cereal | D21: 4 | E21: 454 | F21: S/I | G21: S/I | H21: 19.4 | I21: 51.2 | J21: 36.8 | K21: 1.7 | L21: 19.1 | M21: 7.9 | N21: 8.3 | O21: 2.9 | P21: 0 | Q21: 56.3 | R21: 538 | S21: 65.8 | T21: 8.6 | U21: 10.2 | V21: S/I | W21: 0.4 | X21: 0.7 | Y21: 5.9 | Z21: 0.8 | AA21: S/I | AB21: 1.9 | AC21: 167 | AD21: 207 | AE21: S/I | AF21: 1066 | AG21: 644 | AH21: 92.6 | AI21: 7.1 | AJ21: 6.7 | AK21: 0.3 | AL21: S/I | AM21: 0
A22: 21 | B22: Leche y Derivados | C22: Leche condensada | D22: 1 | E22: 321 | F22: 27.2 | G22: 1.8 | H22: 7.9 | I22: 54.4 | J22: 54.4 | K22: 0 | L22: 8.7 | M22: 5.49 | N22: 2.43 | O22: 0.34 | P22: S/I | Q22: 34 | R22: 74 | S22: 2.6 | T22: 0.2 | U22: 0.2 | V22: 0.6 | W22: 0.1 | X22: 0.4 | Y22: 0.2 | Z22: 0.1 | AA22: 0.8 | AB22: 0.4 | AC22: 11 | AD22: 127 | AE22: 371 | AF22: 284 | AG22: 253 | AH22: 26 | AI22: 0.2 | AJ22: 0.9 | AK22: 0 | AL22: 14.8 | AM22: 0
A23: 22 | B23: Leche y Derivados | C23: Leche evaporada | D23: 1 | E23: 134 | F23: 74 | G23: 1.6 | H23: 6.8 | I23: 10 | J23: 10 | K23: 0 | L23: 7.6 | M23: 4.59 | N23: 2.34 | O23: 0.25 | P23: S/I | Q23: 29 | R23: 65 | S23: 1.9 | T23: 2 | U23: 0.1 | V23: 0.5 | W23: 0.1 | X23: 0.3 | Y23: 0.2 | Z23: 0.1 | AA23: 0.6 | AB23: 0.2 | AC23: 8 | AD23: 106 | AE23: 303 | AF23: 261 | AG23: 203 | AH23: 24 | AI23: 0.2 | AJ23: 0.8 | AK23: 0 | AL23: 2.3 | AM23: 0
A24: 23 | B24: Leche y Derivados | C24: Quesillo | D24: 1 | E24: 103 | F24: 79 | G24: 1.3 | H24: 12.5 | I24: 2.7 | J24: 2.7 | K24: 0 | L24: 4.5 | M24: 2.85 | N24: 1.29 | O24: 0.14 | P24: S/I | Q24: 14.9 | R24: 48.1 | S24: 0 | T24: 0 | U24: 0.6 | V24: 0.1 | W24: 0 | X24: 0.2 | Y24: 0.1 | Z24: 0.1 | AA24: 0.2 | AB24: 0.6 | AC24: 12.2 | AD24: 405 | AE24: 84.3 | AF24: 60 | AG24: 131 | AH24: 5.2 | AI24: 0.1 | AJ24: 0.4 | AK24: 0 | AL24: 6 | AM24: 0
A25: 24 | B25: Leche y Derivados | C25: Quesillo 0% MG | D25: 4 | E25: 85 | F25: 78.7 | G25: 1.7 | H25: 13.9 | I25: 4.4 | J25: 3.8 | K25: 0 | L25: 1.3 | M25: 0.83 | N25: 0.38 | O25: 0.03 | P25: 0.06 | Q25: 4 | R25: 2 | S25: 0 | T25: 0 | U25: 0 | V25: 0 | W25: 0 | X25: 0.2 | Y25: 0.1 | Z25: 0 | AA25: 0.4 | AB25: 0.5 | AC25: 9 | AD25: 260 | AE25: 137 | AF25: 434 | AG25: 190 | AH25: 11 | AI25: 0.1 | AJ25: 0.5 | AK25: 0 | AL25: 9.4 | AM25: 0
A26: 25 | B26: Leche y Derivados | C26: Quesillo sin sal | D26: 4 | E26: 151 | F26: 72.2 | G26: 1.3 | H26: 13 | I26: 4.5 | J26: 3.8 | K26: 0 | L26: 9 | M26: 5.76 | N26: 2.62 | O26: 0.23 | P26: 0.39 | Q26: 29 | R26: 68 | S26: 0 | T26: 0 | U26: 0.1 | V26: 0 | W26: 0 | X26: 0.3 | Y26: 0.1 | Z26: 0.1 | AA26: 0.5 | AB26: 0.5 | AC26: 8 | AD26: 51 | AE26: 125 | AF26: 420 | AG26: 150 | AH26: 9 | AI26: 0.1 | AJ26: 0.5 | AK26: 0 | AL26: 11.9 | AM26: 0
A27: 26 | B27: Leche y Derivados | C27: Queso cabra | D27: 1 | E27: 364 | F27: 45.5 | G27: 2.9 | H27: 21.6 | I27: 0.1 | J27: 0.1 | K27: 0 | L27: 29.8 | M27: 20.64 | N27: 6.81 | O27: 0.71 | P27: S/I | Q27: 79 | R27: 407 | S27: 0 | T27: 0.5 | U27: 0.3 | V27: 2.5 | W27: 0.1 | X27: 0.7 | Y27: 1.2 | Z27: 0.1 | AA27: 0.19 | AB27: 0.2 | AC27: 2 | AD27: 415 | AE27: 158 | AF27: 298 | AG27: 375 | AH27: 29 | AI27: 1.6 | AJ27: 0.7 | AK27: 0.6 | AL27: 3.8 | AM27: 0
A28: 27 | B28: Leche y Derivados | C28: Queso chanco | D28: 3 | E28: 356 | F28: 42.8 | G28: 3.3 | H28: 20.8 | I28: 5.1 | J28: 0.1 | K28: 0 | L28: 28 | M28: 16.34 | N28: 8.82 | O28: 0.44 | P28: 0.9 | Q28: 83 | R28: 161.2 | S28: 0 | T28: 0.5 | U28: 0.2 | V28: 2.2 | W28: 0 | X28: 0.3 | Y28: 0.1 | Z28: 0.1 | AA28: 0.3 | AB28: 1.5 | AC28: 20.5 | AD28: 536 | AE28: 118.2 | AF28: 822 | AG28: 533.5 | AH28: 28.3 | AI28: 0.2 | AJ28: 3.8 | AK28: 0 | AL28: 14.2 | AM28: 0
A29: 28 | B29: Leche y Derivados | C29: Queso cheddar | D29: 1 | E29: 404 | F29: 37 | G29: 3.7 | H29: 22.9 | I29: 3.1 | J29: 0.5 | K29: 0 | L29: 33.3 | M29: 18.87 | N29: 9.25 | O29: 1.42 | P29: 1.16 | Q29: 99 | R29: 330 | S29: 0 | T29: 0.6 | U29: 0.7 | V29: 2.4 | W29: 0 | X29: 0.4 | Y29: 0.1 | Z29: 0.1 | AA29: 0.41 | AB29: 1.1 | AC29: 27 | AD29: 653 | AE29: 76 | AF29: 710 | AG29: 455 | AH29: 27 | AI29: 0.1 | AJ29: 3.6 | AK29: 0 | AL29: 28.5 | AM29: 0
A30: 29 | B30: Leche y Derivados | C30: Queso crema (fuente 1) | D30: 1 | E30: 350 | F30: 52.6 | G30: 1.3 | H30: 6.2 | I30: 5.5 | J30: 3.8 | K30: 0 | L30: 34.4 | M30: 20.21 | N30: 8.91 | O30: 1.48 | P30: 1.17 | Q30: 101 | R30: 308 | S30: 0 | T30: 0 | U30: 0.9 | V30: 2.1 | W30: 0 | X30: 0.2 | Y30: 0.1 | Z30: 0.1 | AA30: 0.52 | AB30: 0.2 | AC30: 9 | AD30: 314 | AE30: 132 | AF30: 97 | AG30: 107 | AH30: 9 | AI30: 0.1 | AJ30: 0.5 | AK30: 0 | AL30: 8.6 | AM30: 0
A31: 30 | B31: Leche y Derivados | C31: Queso crema (fuente 3) | D31: 3 | E31: 218 | F31: 61.6 | G31: 3.5 | H31: 12 | I31: 7.3 | J31: 0 | K31: 0 | L31: 15.6 | M31: 9.85 | N31: 3.94 | O31: 0.25 | P31: 0.7 | Q31: 58.3 | R31: 249.6 | S31: 0 | T31: 0 | U31: 0.7 | V31: 1.7 | W31: 0 | X31: 0.2 | Y31: 0.1 | Z31: 0 | AA31: 0.4 | AB31: 0.2 | AC31: 7.3 | AD31: 763 | AE31: 107 | AF31: 430 | AG31: 86.7 | AH31: 7.3 | AI31: 0.1 | AJ31: 0.4 | AK31: 0 | AL31: 7 | AM31: 0
A32: 31 | B32: Leche y Derivados | C32: Queso fresco (fuente 3) | D32: 3 | E32: 228 | F32: 61.7 | G32: 2.7 | H32: 16.9 | I32: 1.6 | J32: 1.6 | K32: S/I | L32: 17.1 | M32: 11.37 | N32: 4.62 | O32: 0.17 | P32: 0 | Q32: 61 | R32: 176.6 | S32: 0 | T32: 2.1 | U32: 0.3 | V32: 0.8 | W32: 0 | X32: 0.1 | Y32: 0 | Z32: 0.1 | AA32: 0.3 | AB32: 1.3 | AC32: 5.5 | AD32: 401 | AE32: 101.7 | AF32: 446.2 | AG32: 303.5 | AH32: 18.9 | AI32: 0.2 | AJ32: 2 | AK32: 0 | AL32: 15.2 | AM32: 0
A33: 32 | B33: Leche y Derivados | C33: Queso fresco (fuente 4) | D33: 4 | E33: 177 | F33: 67.1 | G33: 3.7 | H33: 12.6 | I33: 4.5 | J33: 3.3 | K33: 0 | L33: 12.1 | M33: 7.74 | N33: 3.52 | O33: 0.3 | P33: 0.5 | Q33: 39 | R33: 224 | S33: 0 | T33: 2.7 | U33: 0.4 | V33: 1 | W33: 0 | X33: 0.2 | Y33: 0 | Z33: 0.1 | AA33: 0.4 | AB33: 1.7 | AC33: 7 | AD33: 254 | AE33: 129 | AF33: 383 | AG33: 385 | AH33: 24 | AI33: 0.2 | AJ33: 2.6 | AK33: 0 | AL33: 19.3 | AM33: 0
A34: 33 | B34: Leche y Derivados | C34: Queso fresco light | D34: 3 | E34: 193 | F34: 66.5 | G34: 2.6 | H34: 13.8 | I34: 3.2 | J34: 0.8 | K34: S/I | L34: 13.9 | M34: 8.83 | N34: 3.94 | O34: 0.41 | P34: S/I | Q34: 64 | R34: 92 | S34: 0 | T34: 0.2 | U34: 0.1 | V34: 1.2 | W34: 0 | X34: 0.2 | Y34: 0.1 | Z34: 0.1 | AA34: 0.1 | AB34: 0.6 | AC34: 6.5 | AD34: 363 | AE34: 60.9 | AF34: 566.8 | AG34: 335.6 | AH34: 16.7 | AI34: 0.2 | AJ34: 2 | AK34: 0 | AL34: 10.4 | AM34: 0
A35: 34 | B35: Leche y Derivados | C35: Queso gouda (fuente 1) | D35: 1 | E35: 356 | F35: 41.5 | G35: 3.9 | H35: 24.9 | I35: 2.2 | J35: 2.2 | K35: 0 | L35: 27.4 | M35: 17.61 | N35: 7.75 | O35: 0.66 | P35: S/I | Q35: 114 | R35: 165 | S35: 0 | T35: 0.5 | U35: 0.2 | V35: 2.3 | W35: 0 | X35: 0.3 | Y35: 0.1 | Z35: 0.1 | AA35: 0.3 | AB35: 1.5 | AC35: 21 | AD35: 819 | AE35: 121 | AF35: 700 | AG35: 546 | AH35: 29 | AI35: 0.2 | AJ35: 3.9 | AK35: 0 | AL35: 14.5 | AM35: 0
A36: 35 | B36: Leche y Derivados | C36: Queso gouda (fuente 3) | D36: 3 | E36: 341 | F36: 42.7 | G36: 3 | H36: 24.8 | I36: 4.8 | J36: 0 | K36: 0 | L36: 24.7 | M36: 15.55 | N36: 6.79 | O36: 0.47 | P36: 0.5 | Q36: 114 | R36: 161.5 | S36: 0 | T36: 0.5 | U36: 0.2 | V36: 2.3 | W36: 0 | X36: 0.3 | Y36: 0.1 | Z36: 0.1 | AA36: 0.3 | AB36: 1.5 | AC36: 20.6 | AD36: 259 | AE36: 118.4 | AF36: 850 | AG36: 534.4 | AH36: 28.4 | AI36: 0.2 | AJ36: 3.8 | AK36: 0 | AL36: 14.2 | AM36: 0
A37: 36 | B37: Leche y Derivados | C37: Queso mantecoso | D37: 3 | E37: 394 | F37: 35.2 | G37: 2.9 | H37: 24.7 | I37: 8 | J37: 0 | K37: S/I | L37: 29.2 | M37: 18.93 | N37: 7.13 | O37: 0.66 | P37: 0.9 | Q37: 85.4 | R37: 331.6 | S37: 0 | T37: 0.7 | U37: 0.3 | V37: 2.8 | W37: 0 | X37: 0.4 | Y37: 0.1 | Z37: 0.1 | AA37: 0.2 | AB37: 1.6 | AC37: 13.4 | AD37: 452 | AE37: 149.1 | AF37: 797.9 | AG37: 520.8 | AH37: 30 | AI37: 0.5 | AJ37: 3.1 | AK37: 0 | AL37: 16.1 | AM37: 0
A38: 37 | B38: Leche y Derivados | C38: Queso mozzarella | D38: 3 | E38: 199 | F38: 66.7 | G38: 2.4 | H38: 13.5 | I38: 2.3 | J38: 1.3 | K38: 0 | L38: 15.1 | M38: 9.4 | N38: 3.92 | O38: 0.59 | P38: 0.4 | Q38: 44.9 | R38: 119.2 | S38: 0 | T38: 0.3 | U38: 0.1 | V38: 1.5 | W38: 0 | X38: 0.2 | Y38: 0.1 | Z38: 0 | AA38: 0.1 | AB38: 1.5 | AC38: 4.7 | AD38: 507 | AE38: 50.6 | AF38: 336.4 | AG38: 235.8 | AH38: 13.3 | AI38: 0.3 | AJ38: 1.9 | AK38: 0 | AL38: 11.3 | AM38: 0
A39: 38 | B39: Leche y Derivados | C39: Queso parmesano (fuente 2) | D39: 2 | E39: 476 | F39: 10.3 | G39: 7.6 | H39: 47.1 | I39: 5.5 | J39: 0.1 | K39: S/I | L39: 29.5 | M39: 17.52 | N39: 8.87 | O39: 0.67 | P39: S/I | Q39: 68 | R39: 142 | S39: 0 | T39: 0.6 | U39: 0.3 | V39: 2.2 | W39: 0 | X39: 0.4 | Y39: 0.3 | Z39: 0.1 | AA39: 0.6 | AB39: 1.5 | AC39: 9 | AD39: 1176 | AE39: 117.9 | AF39: 1653 | AG39: 889.3 | AH39: 56.4 | AI39: 1.1 | AJ39: 3.5 | AK39: 0 | AL39: 28.8 | AM39: 0
A40: 39 | B40: Leche y Derivados | C40: Queso parmesano (fuente 1) | D40: 1 | E40: 420 | F40: 22.7 | G40: 7.2 | H40: 28.4 | I40: 13.9 | J40: 0.1 | K40: 0 | L40: 27.8 | M40: 15.37 | N40: 7.13 | O40: 1.39 | P40: S/I | Q40: 86 | R40: 262 | S40: 0 | T40: 0.5 | U40: 0.5 | V40: 1.7 | W40: 0 | X40: 0.4 | Y40: 0.1 | Z40: 0.1 | AA40: 0.5 | AB40: 1.4 | AC40: 6 | AD40: 1804 | AE40: 180 | AF40: 853 | AG40: 627 | AH40: 34 | AI40: 0.5 | AJ40: 4.2 | AK40: 0 | AL40: 34.4 | AM40: 0
...

Sheet Fuentes
A1: Código | B1: Fuente
A2: 1 | B2: USDA Food Composition Databases (EE.UU.)
A3: 2 | B3: Tabla de Composición Química de Alimentos Chilenos (Schmidt-Hebbel y cols., 1990)
A4: 3 | B4: Análisis del Centro de Alimentos INTA, Universidad de Chile
A5: 4 | B5: Etiquetado nutricional de productos del mercado
A6: 6 | B6: Jury G. y cols. Porciones de intercambio y composición química de los alimentos de la Pirámide Alimentaria Chilena, 1997
B8: Valores por 100 g/ml de alimento. Transcrito de: Tabla de Composición de Alimentos, INTA – Universidad de Chile, 2018.
B9: S/I = sin información. 'Trazas' = cantidad mínima no cuantificada.
B10: Alcohol (g) solo aparece en la sección Bebidas Alcohólicas; en el resto queda S/I.
B11: En Cyclinex, Dialamine, Glutarex, Ketonex, Phenex, Propimex, Tyrex, PKU y MMA-PA las proteínas son aminoácidos (proteína equivalente).
B13: VALORES COMPLETADOS (celdas lila en cursiva en la pestaña Datos):
B14: Los S/I se completaron con USDA FoodData Central, SR Legacy (abril 2018), dominio público: https://fdc.nal.usda.gov/
B15: Cada producto se emparejó con el alimento USDA más parecido; la pestaña 'Valores completados' lista cada valor, el método y el alimento USDA.
B16: Vitaminas y minerales se ajustaron por materia seca: valor USDA × (100 − humedad del producto) / (100 − humedad USDA).
B17: Ácidos grasos: proporción USDA aplicada a los lípidos totales del producto. Azúcares nunca superan los HdeC disponibles.
B18: Humedad y cenizas faltantes se calcularon por diferencia con el resto de la composición. Alcohol = 0 en alimentos no alcohólicos.
B19: Quedan S/I cuando no hubo equivalente razonable (fórmulas especiales, platos preparados, algunos productos locales).
B20: Los valores originales de la tabla INTA no se modificaron. Son estimaciones: verifícalas antes de un uso clínico.

Sheet Lista
A1: Producto | B1: Coincidencia N° | C1: k | D1: Lista filtrada
A2: =Datos!C2 -> Leche materna | B2: =IF(ISNUMBER(SEARCH(Calculadora!$C$4,A2)),MAX(B$1:B1)+1,"") | C2: 1 | D2: =IFERROR(INDEX($A$2:$A$647,MATCH(C2,$B$2:$B$647,0)),"") -> Leche en polvo 26% MG con Vit. D
A3: =Datos!C3 -> Leche de burra | B3: =IF(ISNUMBER(SEARCH(Calculadora!$C$4,A3)),MAX(B$1:B2)+1,"") | C3: 2 | D3: =IFERROR(INDEX($A$2:$A$647,MATCH(C3,$B$2:$B$647,0)),"")
A4: =Datos!C4 -> Leche de cabra con Vit. D | B4: =IF(ISNUMBER(SEARCH(Calculadora!$C$4,A4)),MAX(B$1:B3)+1,"") | C4: 3 | D4: =IFERROR(INDEX($A$2:$A$647,MATCH(C4,$B$2:$B$647,0)),"")
A5: =Datos!C5 -> Leche fluida entera (fuente 1) | B5: =IF(ISNUMBER(SEARCH(Calculadora!$C$4,A5)),MAX(B$1:B4)+1,"") | C5: 4 | D5: =IFERROR(INDEX($A$2:$A$647,MATCH(C5,$B$2:$B$647,0)),"")
A6: =Datos!C6 -> Leche fluida entera (fuente 2) | B6: =IF(ISNUMBER(SEARCH(Calculadora!$C$4,A6)),MAX(B$1:B5)+1,"") | C6: 5 | D6: =IFERROR(INDEX($A$2:$A$647,MATCH(C6,$B$2:$B$647,0)),"")
A7: =Datos!C7 -> Leche entera con sabor | B7: =IF(ISNUMBER(SEARCH(Calculadora!$C$4,A7)),MAX(B$1:B6)+1,"") | C7: 6 | D7: =IFERROR(INDEX($A$2:$A$647,MATCH(C7,$B$2:$B$647,0)),"")
A8: =Datos!C8 -> Leche semidescremada | B8: =IF(ISNUMBER(SEARCH(Calculadora!$C$4,A8)),MAX(B$1:B7)+1,"") | C8: 7 | D8: =IFERROR(INDEX($A$2:$A$647,MATCH(C8,$B$2:$B$647,0)),"")
A9: =Datos!C9 -> Leche semidescremada con sabor | B9: =IF(ISNUMBER(SEARCH(Calculadora!$C$4,A9)),MAX(B$1:B8)+1,"") | C9: 8 | D9: =IFERROR(INDEX($A$2:$A$647,MATCH(C9,$B$2:$B$647,0)),"")
A10: =Datos!C10 -> Leche semidescremada con sabor chocolate | B10: =IF(ISNUMBER(SEARCH(Calculadora!$C$4,A10)),MAX(B$1:B9)+1,"") | C10: 9 | D10: =IFERROR(INDEX($A$2:$A$647,MATCH(C10,$B$2:$B$647,0)),"")
A11: =Datos!C11 -> Leche semidescremada con sabor frutilla | B11: =IF(ISNUMBER(SEARCH(Calculadora!$C$4,A11)),MAX(B$1:B10)+1,"") | C11: 10 | D11: =IFERROR(INDEX($A$2:$A$647,MATCH(C11,$B$2:$B$647,0)),"")
A12: =Datos!C12 -> Leche semidescremada sin lactosa | B12: =IF(ISNUMBER(SEARCH(Calculadora!$C$4,A12)),MAX(B$1:B11)+1,"") | C12: 11 | D12: =IFERROR(INDEX($A$2:$A$647,MATCH(C12,$B$2:$B$647,0)),"")
A13: =Datos!C13 -> Leche descremada (fuente 4) | B13: =IF(ISNUMBER(SEARCH(Calculadora!$C$4,A13)),MAX(B$1:B12)+1,"") | C13: 12 | D13: =IFERROR(INDEX($A$2:$A$647,MATCH(C13,$B$2:$B$647,0)),"")
... A431: =Datos!C431 -> Níspero | B431: =IF(ISNUMBER(SEARCH(Calculadora!$C$4,A431)),MAX(B$1:B430)+1,"") | C431: 430 | D431: =IFERROR(INDEX($A$2:$A$647,MATCH(C431,$B$2:$B$647,0)),"")
A432: =Datos!C433 -> Palta | B432: =IF(ISNUMBER(SEARCH(Calculadora!$C$4,A432)),MAX(B$1:B431)+1,"") | C432: 431 | D432: =IFERROR(INDEX($A$2:$A$647,MATCH(C432,$B$2:$B$647,0)),"")
A433: =Datos!C434 -> Palta hass | B433: =IF(ISNUMBER(SEARCH(Calculadora!$C$4,A433)),MAX(B$1:B432)+1,"") | C433: 432 | D433: =IFERROR(INDEX($A$2:$A$647,MATCH(C433,$B$2:$B$647,0)),"")
A434: =Datos!C435 -> Papaya | B434: =IF(ISNUMBER(SEARCH(Calculadora!$C$4,A434)),MAX(B$1:B433)+1,"") | C434: 433 | D434: =IFERROR(INDEX($A$2:$A$647,MATCH(C434,$B$2:$B$647,0)),"")
A435: =Datos!C436 -> Pasas | B435: =IF(ISNUMBER(SEARCH(Calculadora!$C$4,A435)),MAX(B$1:B434)+1,"") | C435: 434 | D435: =IFERROR(INDEX($A$2:$A$647,MATCH(C435,$B$2:$B$647,0)),"")
A436: =Datos!C437 -> Pepino dulce | B436: =IF(ISNUMBER(SEARCH(Calculadora!$C$4,A436)),MAX(B$1:B435)+1,"") | C436: 435 | D436: =IFERROR(INDEX($A$2:$A$647,MATCH(C436,$B$2:$B$647,0)),"")
A437: =Datos!C438 -> Azúcar | B437: =IF(ISNUMBER(SEARCH(Calculadora!$C$4,A437)),MAX(B$1:B436)+1,"") | C437: 436 | D437: =IFERROR(INDEX($A$2:$A$647,MATCH(C437,$B$2:$B$647,0)),"")
A438: =Datos!C439 -> Azúcar (contiene sorbitol) | B438: =IF(ISNUMBER(SEARCH(Calculadora!$C$4,A438)),MAX(B$1:B437)+1,"") | C438: 437 | D438: =IFERROR(INDEX($A$2:$A$647,MATCH(C438,$B$2:$B$647,0)),"")
A439: =Datos!C440 -> Azúcar flor | B439: =IF(ISNUMBER(SEARCH(Calculadora!$C$4,A439)),MAX(B$1:B438)+1,"") | C439: 438 | D439: =IFERROR(INDEX($A$2:$A$647,MATCH(C439,$B$2:$B$647,0)),"")
A440: =Datos!C441 -> Azúcar light con estevia | B440: =IF(ISNUMBER(SEARCH(Calculadora!$C$4,A440)),MAX(B$1:B439)+1,"") | C440: 439 | D440: =IFERROR(INDEX($A$2:$A$647,MATCH(C440,$B$2:$B$647,0)),"")
A441: =Datos!C442 -> Azúcar light con sucralosa | B441: =IF(ISNUMBER(SEARCH(Calculadora!$C$4,A441)),MAX(B$1:B440)+1,"") | C441: 440 | D441: =IFERROR(INDEX($A$2:$A$647,MATCH(C441,$B$2:$B$647,0)),"")
A442: =Datos!C443 -> Miel de abeja (fuente 3) | B442: =IF(ISNUMBER(SEARCH(Calculadora!$C$4,A442)),MAX(B$1:B441)+1,"") | C442: 441 | D442: =IFERROR(INDEX($A$2:$A$647,MATCH(C442,$B$2:$B$647,0)),"")
A443: =Datos!C444 -> Miel de abeja (fuente 2) | B443: =IF(ISNUMBER(SEARCH(Calculadora!$C$4,A443)),MAX(B$1:B442)+1,"") | C443: 442 | D443: =IFERROR(INDEX($A$2:$A$647,MATCH(C443,$B$2:$B$647,0)),"")
... A647: =Datos!C648 -> XPHEN TYR Maxamum | B647: =IF(ISNUMBER(SEARCH(Calculadora!$C$4,A647)),MAX(B$1:B646)+1,"") | C647: 646 | D647: =IFERROR(INDEX($A$2:$A$647,MATCH(C647,$B$2:$B$647,0)),"")

Sheet Valores completados
A1: Producto | B1: Nutriente | C1: Unidad | D1: Valor estimado | E1: Método | F1: Alimento USDA usado | G1: FDC ID
A2: Leche materna | B2: Alcohol | C2: g | D2: 0 | E2: 0: no es bebida alcohólica
A3: Leche de burra | B3: Alcohol | C3: g | D3: 0 | E3: 0: no es bebida alcohólica
A4: Leche de cabra con Vit. D | B4: Alcohol | C4: g | D4: 0 | E4: 0: no es bebida alcohólica
A5: Leche fluida entera (fuente 1) | B5: Azúcares totales | C5: g | D5: 4.7 | E5: USDA ajustado a materia seca | F5: Milk, whole, 3.25% milkfat, without added vitamin A and vitamin D | G5: 172217
A6: Leche fluida entera (fuente 1) | B6: Vitamina D | C6: ug | D6: 0.1 | E6: USDA ajustado a materia seca | F6: Milk, whole, 3.25% milkfat, without added vitamin A and vitamin D | G6: 172217
A7: Leche fluida entera (fuente 1) | B7: Vitamina E | C7: mg ET | D7: 0.1 | E7: USDA ajustado a materia seca | F7: Milk, whole, 3.25% milkfat, without added vitamin A and vitamin D | G7: 172217
A8: Leche fluida entera (fuente 1) | B8: Vitamina K | C8: ug | D8: 0.3 | E8: USDA ajustado a materia seca | F8: Milk, whole, 3.25% milkfat, without added vitamin A and vitamin D | G8: 172217
A9: Leche fluida entera (fuente 1) | B9: Alcohol | C9: g | D9: 0 | E9: 0: no es bebida alcohólica
A10: Leche fluida entera (fuente 2) | B10: Azúcares totales | C10: g | D10: 5.1 | E10: USDA ajustado a materia seca | F10: Milk, whole, 3.25% milkfat, without added vitamin A and vitamin D | G10: 172217
A11: Leche fluida entera (fuente 2) | B11: Vitamina D | C11: ug | D11: 0.1 | E11: USDA ajustado a materia seca | F11: Milk, whole, 3.25% milkfat, without added vitamin A and vitamin D | G11: 172217
A12: Leche fluida entera (fuente 2) | B12: Vitamina E | C12: mg ET | D12: 0.1 | E12: USDA ajustado a materia seca | F12: Milk, whole, 3.25% milkfat, without added vitamin A and vitamin D | G12: 172217
A13: Leche fluida entera (fuente 2) | B13: Vitamina K | C13: ug | D13: 0.3 | E13: USDA ajustado a materia seca | F13: Milk, whole, 3.25% milkfat, without added vitamin A and vitamin D | G13: 172217
A14: Leche fluida entera (fuente 2) | B14: Selenio | C14: ug | D14: 3.7 | E14: USDA ajustado a materia seca | F14: Milk, whole, 3.25% milkfat, without added vitamin A and vitamin D | G14: 172217
A15: Leche fluida entera (fuente 2) | B15: Alcohol | C15: g | D15: 0 | E15: 0: no es bebida alcohólica
A16: Leche entera con sabor | B16: Azúcares totales | C16: g | D16: 9.2 | E16: USDA ajustado a materia seca | F16: Milk, chocolate, fluid, commercial, whole, with added vitamin A and vitamin D | G16: 170879
A17: Leche entera con sabor | B17: Vitamina D | C17: ug | D17: 1.3 | E17: USDA ajustado a materia seca | F17: Milk, chocolate, fluid, commercial, whole, with added vitamin A and vitamin D | G17: 170879
A18: Leche entera con sabor | B18: Vitamina K | C18: ug | D18: 0.3 | E18: USDA ajustado a materia seca | F18: Milk, chocolate, fluid, commercial, whole, with added vitamin A and vitamin D | G18: 170879
A19: Leche entera con sabor | B19: Alcohol | C19: g | D19: 0 | E19: 0: no es bebida alcohólica
A20: Leche semidescremada | B20: Ác. grasos saturados | C20: g | D20: 0.83 | E20: USDA, proporcional a los lípidos totales del producto | F20: Milk, reduced fat, fluid, 2% milkfat, with added vitamin A and vitamin D | G20: 171267
A21: Leche semidescremada | B21: Ác. grasos monoinsaturados | C21: g | D21: 0.37 | E21: USDA, proporcional a los lípidos totales del producto | F21: Milk, reduced fat, fluid, 2% milkfat, with added vitamin A and vitamin D | G21: 171267
A22: Leche semidescremada | B22: Ác. grasos poliinsaturados | C22: g | D22: 0.05 | E22: USDA, proporcional a los lípidos totales del producto | F22: Milk, reduced fat, fluid, 2% milkfat, with added vitamin A and vitamin D | G22: 171267
A23: Leche semidescremada | B23: Ác. grasos trans | C23: g | D23: 0.06 | E23: USDA, proporcional a los lípidos totales del producto | F23: Milk, reduced fat, fluid, 2% milkfat, with added vitamin A and vitamin D | G23: 171267
A24: Leche semidescremada | B24: Colesterol | C24: mg | D24: 8 | E24: USDA | F24: Milk, reduced fat, fluid, 2% milkfat, with added vitamin A and vitamin D | G24: 171267
A25: Leche semidescremada | B25: Vitamina A | C25: ug EAR | D25: 50 | E25: USDA ajustado a materia seca | F25: Milk, reduced fat, fluid, 2% milkfat, with added vitamin A and vitamin D | G25: 171267
A26: Leche semidescremada | B26: Vitamina C | C26: mg | D26: 0.2 | E26: USDA ajustado a materia seca | F26: Milk, reduced fat, fluid, 2% milkfat, with added vitamin A and vitamin D | G26: 171267
A27: Leche semidescremada | B27: Vitamina D | C27: ug | D27: 1.1 | E27: USDA ajustado a materia seca | F27: Milk, reduced fat, fluid, 2% milkfat, with added vitamin A and vitamin D | G27: 171267
A28: Leche semidescremada | B28: Vitamina E | C28: mg ET | D28: 0 | E28: USDA ajustado a materia seca | F28: Milk, reduced fat, fluid, 2% milkfat, with added vitamin A and vitamin D | G28: 171267
A29: Leche semidescremada | B29: Vitamina K | C29: ug | D29: 0.2 | E29: USDA ajustado a materia seca | F29: Milk, reduced fat, fluid, 2% milkfat, with added vitamin A and vitamin D | G29: 171267
A30: Leche semidescremada | B30: Vitamina B1 | C30: mg | D30: 0 | E30: USDA ajustado a materia seca | F30: Milk, reduced fat, fluid, 2% milkfat, with added vitamin A and vitamin D | G30: 171267
A31: Leche semidescremada | B31: Vitamina B2 | C31: mg | D31: 0.2 | E31: USDA ajustado a materia seca | F31: Milk, reduced fat, fluid, 2% milkfat, with added vitamin A and vitamin D | G31: 171267
... A45: Leche semidescremada | B45: Selenio | C45: ug | D45: 2.3 | E45: USDA ajustado a materia seca | F45: Milk, reduced fat, fluid, 2% milkfat, with added vitamin A and vitamin D | G45: 171267
A46: Leche semidescremada | B46: Alcohol | C46: g | D46: 0 | E46: 0: no es bebida alcohólica
A47: Leche semidescremada con sabor | B47: Alcohol | C47: g | D47: 0 | E47: 0: no es bebida alcohólica
A48: Leche semidescremada con sabor chocolate | B48: Cenizas | C48: g | D48: 0.8 | E48: USDA ajustado a materia seca | F48: Milk, chocolate, lowfat, reduced sugar | G48: 170910
A49: Leche semidescremada con sabor chocolate | B49: Fibra dietética total | C49: g | D49: 0 | E49: USDA | F49: Milk, chocolate, lowfat, reduced sugar | G49: 170910
A50: Leche semidescremada con sabor chocolate | B50: Vitamina C | C50: mg | D50: 0 | E50: USDA | F50: Milk, chocolate, lowfat, reduced sugar | G50: 170910
A51: Leche semidescremada con sabor chocolate | B51: Vitamina K | C51: ug | D51: 0.1 | E51: USDA | F51: Milk, chocolate, lowfat, reduced sugar | G51: 170910
A52: Leche semidescremada con sabor chocolate | B52: Vitamina B1 | C52: mg | D52: 0 | E52: USDA | F52: Milk, chocolate, lowfat, reduced sugar | G52: 170910
A53: Leche semidescremada con sabor chocolate | B53: Vitamina B2 | C53: mg | D53: 0.2 | E53: USDA | F53: Milk, chocolate, lowfat, reduced sugar | G53: 170910
...
